<?xml version="1.0" ?>
<!-- =================================================================================== -->
<!-- |    This document was autogenerated by xacro from /home/bot/catkin_ws/src/cyton_gamma_1500_description/cyton_gamma_1500.urdf.xacro | -->
<!-- |    EDITING THIS FILE BY HAND IS NOT RECOMMENDED                                 | -->
<!-- =================================================================================== -->
<robot name="cyton_gamma_1500" xmlns:xacro="http://www.ros.org/wiki/xacro">
  <link name="base_footprint">
    <visual>
      <origin rpy="0 0 0" xyz="0 0 0"/>
      <geometry>
        <sphere radius="0.001"/>
      </geometry>
      <material name="white">
        <color rgba="1 1 1 1"/>
      </material>
    </visual>
  </link>
  <joint name="base_joint" type="fixed">
    <parent link="base_footprint"/>
    <child link="base_link"/>
    <origin rpy="0 0 0" xyz="0.0 0.0 0.0"/>
  </joint>
  <link name="base_link">
    <visual>
      <origin rpy="0 0 0" xyz="0 0 0"/>
      <geometry>
        <mesh filename="package://cyton_gamma_1500_description/meshes/base.dae"/>
      </geometry>
    </visual>
    <collision>
      <origin xyz="0 0.0115 0.047"/>
      <geometry>
        <box size="0.154 0.177 0.094"/>
      </geometry>
    </collision>
  </link>
  <joint name="shoulder_roll_joint" type="revolute">
    <parent link="base_link"/>
    <child link="shoulder_roll"/>
    <origin rpy="0 0 0" xyz="0 0 0.053"/>
    <limit effort="100.0" lower="-2.618" upper="2.618" velocity="1.0"/>
    <axis xyz="0 0 1"/>
  </joint>
  <link name="shoulder_roll">
    <visual>
      <origin rpy="0 -1.5708 3.5256" xyz="0 0 0"/>
      <geometry>
        <mesh filename="package://cyton_gamma_1500_description/meshes/shoulder_roll.dae"/>
      </geometry>
    </visual>
    <collision>
      <origin xyz="0.069 0.0055 0.0544"/>
      <geometry>
        <box size="0.18143 0.0839 0.0955"/>
      </geometry>
    </collision>
  </link>
  <joint name="shoulder_pitch_joint" type="revolute">
    <parent link="shoulder_roll"/>
    <child link="shoulder_pitch"/>
    <origin rpy="0 0 0" xyz="0.0205 0 0.12435"/>
    <limit effort="100.0" lower="-1.8326" upper="1.8326" velocity="1.0"/>
    <axis xyz="1 0 0"/>
  </joint>
  <link name="shoulder_pitch">
    <visual>
      <origin rpy="1.5708 0 0" xyz="0 0 0"/>
      <geometry>
        <mesh filename="package://cyton_gamma_1500_description/meshes/shoulder_pitch.dae"/>
      </geometry>
    </visual>
    <collision>
      <origin xyz="-0.001 0.064 0.1759"/>
      <geometry>
        <box size="0.0709 0.1936 0.08"/>
      </geometry>
    </collision>
  </link>
  <joint name="shoulder_yaw_joint" type="revolute">
    <parent link="shoulder_pitch"/>
    <child link="shoulder_yaw"/>
    <origin rpy="0 0 0" xyz="-0.0215 -0.0205 0.1255"/>
    <limit effort="100.0" lower="-1.8326" upper="1.8326" velocity="1.0"/>
    <axis xyz="0 -1 0"/>
  </joint>
  <link name="shoulder_yaw">
    <visual>
      <origin rpy="1.5708 0 -1.5708" xyz="0 0 0.0"/>
      <geometry>
        <mesh filename="package://cyton_gamma_1500_description/meshes/shoulder_yaw.dae"/>
      </geometry>
    </visual>
    <collision>
      <origin xyz="-0.0225 0.039 0.3052"/>
      <geometry>
        <box size="0.0717 0.1846 0.0726"/>
      </geometry>
    </collision>
  </link>
  <joint name="elbow_pitch_joint" type="revolute">
    <parent link="shoulder_yaw"/>
    <child link="elbow_pitch"/>
    <origin rpy="0 0 0" xyz="0.018 0.0215 0.1158"/>
    <limit effort="100.0" lower="-1.8326" upper="1.8326" velocity="1.0"/>
    <axis xyz="1 0 0"/>
  </joint>
  <link name="elbow_pitch">
    <visual>
      <origin rpy="1.5708 0 3.1416" xyz="0 0 0"/>
      <geometry>
        <mesh filename="package://cyton_gamma_1500_description/meshes/elbow_pitch.dae"/>
      </geometry>
    </visual>
    <collision>
      <origin xyz="0.0346 0.046 0.4214"/>
      <geometry>
        <box size="0.0549 0.1556 0.0735"/>
      </geometry>
    </collision>
  </link>
  <joint name="elbow_yaw_joint" type="revolute">
    <parent link="elbow_pitch"/>
    <child link="elbow_yaw"/>
    <origin rpy="0 0 0" xyz="-0.0185 -0.018 0.0973"/>
    <limit effort="100.0" lower="-1.8326" upper="1.8326" velocity="1.0"/>
    <axis xyz="0 -1 0"/>
  </joint>
  <link name="elbow_yaw">
    <visual>
      <origin rpy="1.5708 0 1.5708" xyz="0 0 0"/>
      <geometry>
        <mesh filename="package://cyton_gamma_1500_description/meshes/elbow_yaw.dae"/>
      </geometry>
    </visual>
    <collision>
      <origin xyz="0.0162 0.0211 0.516"/>
      <geometry>
        <box size="0.0535 0.1165 0.0402"/>
      </geometry>
    </collision>
  </link>
  <joint name="wrist_pitch_joint" type="revolute">
    <parent link="elbow_yaw"/>
    <child link="wrist_pitch"/>
    <origin rpy="0 0 0" xyz="0.02325 0.018 0.0718"/>
    <limit effort="100.0" lower="-1.8326" upper="1.8326" velocity="1.0"/>
    <axis xyz="1 0 0"/>
  </joint>
  <link name="wrist_pitch">
    <visual>
      <origin rpy="1.5708 0 1.5708" xyz="0 0 0"/>
      <geometry>
        <mesh filename="package://cyton_gamma_1500_description/meshes/wrist_pitch.dae"/>
      </geometry>
    </visual>
    <collision>
      <origin xyz="0.0248 0.0118 0.5614"/>
      <geometry>
        <box size="0.026 0.0435 0.0519"/>
      </geometry>
    </collision>
  </link>
  <joint name="wrist_roll_joint" type="revolute">
    <parent link="wrist_pitch"/>
    <child link="wrist_roll"/>
    <origin rpy="0 0 0" xyz="-0.02625 0 0.05142"/>
    <limit effort="100.0" lower="-2.61799" upper="2.61799" velocity="1.0"/>
    <axis xyz="0 0 1"/>
  </joint>
  <link name="wrist_roll">
    <visual>
      <origin rpy="3.1416 0 -1.5708" xyz="0 0 0"/>
      <geometry>
        <mesh filename="package://cyton_gamma_1500_description/meshes/wrist_roll.dae"/>
      </geometry>
    </visual>
    <collision>
      <origin xyz="0.0022 -0.003 0.6042"/>
      <geometry>
        <box size="0.0546 0.0745 0.1118"/>
      </geometry>
    </collision>
  </link>
  <joint name="gripper_joint" type="prismatic">
    <parent link="wrist_roll"/>
    <child link="gripper_finger1"/>
    <origin rpy="0 0 0" xyz="0.008 -0.00305 0.08868"/>
    <limit effort="100.0" lower="-0.008" upper="0.008" velocity="1.0"/>
    <axis xyz="1 0 0"/>
  </joint>
  <link name="gripper_finger1">
    <visual>
      <origin rpy="0 0 0" xyz="0 0 0"/>
      <geometry>
        <mesh filename="package://cyton_gamma_1500_description/meshes/gripper_finger1.dae"/>
      </geometry>
    </visual>
    <collision>
      <origin xyz="0.0135 0.0093 0.7365"/>
      <geometry>
        <box size="0.015 0.0229 0.0475"/>
      </geometry>
    </collision>
  </link>
  <joint name="gripper_joint2" type="prismatic">
    <parent link="wrist_roll"/>
    <child link="gripper_finger2"/>
    <origin rpy="0 0 0" xyz="-0.008 -0.00305 0.08868"/>
    <limit effort="100.0" lower="-0.008" upper="0.008" velocity="1.0"/>
    <mimic joint="gripper_joint" multiplier="-1"/>
    <axis xyz="1 0 0"/>
  </joint>
  <link name="gripper_finger2">
    <visual>
      <origin rpy="0 0 0" xyz="0 0 0"/>
      <geometry>
        <mesh filename="package://cyton_gamma_1500_description/meshes/gripper_finger2.dae"/>
      </geometry>
    </visual>
    <collision>
      <origin xyz="-0.0175 0.0093 0.7365"/>
      <geometry>
        <box size="0.015 0.0229 0.0475"/>
      </geometry>
    </collision>
  </link>
  <joint name="virtual_endeffector_joint" type="fixed">
    <parent link="wrist_roll"/>
    <child link="virtual_endeffector"/>
    <origin rpy="0 0 0" xyz="0 0 0.090875"/>
  </joint>
  <link name="virtual_endeffector">
    <visual>
      <origin rpy="0 0 0" xyz="0 0 0"/>
      <geometry>
        <sphere radius="0.002"/>
      </geometry>
      <material name="grey">
        <color rgba="0.7 0.7 0.7 0.8"/>
      </material>
    </visual>
  </link>
</robot>
